<?xml version="1.0" encoding="utf-8"?>
<!-- =================================================================================== -->
<!-- |    This document was autogenerated by xacro from raspimouse.urdf.xacro          | -->
<!-- |    EDITING THIS FILE BY HAND IS NOT RECOMMENDED                                 | -->
<!-- =================================================================================== -->
<robot name="raspimouse_on_gazebo" xmlns:controller="http://playerstage.sourceforge.net/gazebo/xmlschema/#controller" xmlns:interface="http://playerstage.sourceforge.net/gazebo/xmlschema/#interface" xmlns:sensor="http://playerstage.sourceforge.net/gazebo/xmlschema/#sensor">
  <!-- =============== Link & Joint =============== -->
  <!-- Base -->
  <link name="base_footprint"/>
  <!-- Main link starting point -->
  <joint name="base_joint" type="fixed">
    <origin xyz="0 0 0.00185"/>
    <parent link="base_footprint"/>
    <child link="base_link"/>
  </joint>
  <link name="base_link">
    <visual>
      <geometry>
        <mesh filename="package://raspimouse_description/meshes/dae/body/RasPiMouse_body.dae"/>
      </geometry>
    </visual>
    <collision>
      <geometry>
        <mesh filename="package://raspimouse_description/meshes/dae/body/RasPiMouse_body.dae"/>
      </geometry>
    </collision>
    <inertial>
      <!-- NOTE BEGINNING -->
      <!-- Biased origin causes the slipping problem. -->
      <!-- Not solved yet. -->
      <!-- NOTE END -->
      <!-- real origin -->
      <!-- <origin xyz="&#45;0.005075 &#45;0.000427 0.029879"/> -->
      <!-- virtual origin -->
      <origin xyz="-0.001 0.0 0.029879"/>
      <mass value="0.7186"/>
      <inertia ixx="0.001238161833" ixy="0.000000904986" ixz="0.000100297310" iyy="0.001368529369" iyz="0.000022118177" izz="0.000784319117"/>
    </inertial>
  </link>
  <joint name="right_wheel_joint" type="continuous">
    <origin rpy="1.57 0 0" xyz="0 -0.0425 0.02215"/>
    <axis xyz="0 0 -1"/>
    <parent link="base_link"/>
    <child link="right_wheel"/>
    <limit effort="70" velocity="15"/>
    <safety_controller k_velocity="10"/>
    <dynamics damping="1.0" friction="1.0"/>
  </joint>
  <link name="right_wheel">
    <visual>
      <geometry>
        <mesh filename="package://raspimouse_description/meshes/dae/wheel/RasPiMouse_wheel.dae"/>
      </geometry>
    </visual>
    <collision>
      <!-- <xacro:insert_block name="joint_origin"/> -->
      <geometry>
        <!-- <cylinder radius="${wheel_radius}" length="${wheel_length}"/> -->
        <mesh filename="package://raspimouse_description/meshes/dae/wheel/RasPiMouse_wheel.dae"/>
      </geometry>
    </collision>
    <inertial>
      <origin xyz="-0.000107 0 0.002875"/>
      <mass value="0.0113"/>
      <inertia ixx="0.000002208187" ixy="0.000000000001" ixz="0.000000004787" iyy="0.00000218412" iyz="0.000000000003" izz="0.000004078299"/>
    </inertial>
  </link>
  <joint name="left_wheel_joint" type="continuous">
    <origin rpy="-1.57 0 0" xyz="0 0.0425 0.02215"/>
    <axis xyz="0 0 1"/>
    <parent link="base_link"/>
    <child link="left_wheel"/>
    <limit effort="70" velocity="15"/>
    <safety_controller k_velocity="10"/>
    <dynamics damping="1.0" friction="1.0"/>
  </joint>
  <link name="left_wheel">
    <visual>
      <geometry>
        <mesh filename="package://raspimouse_description/meshes/dae/wheel/RasPiMouse_wheel.dae"/>
      </geometry>
    </visual>
    <collision>
      <!-- <xacro:insert_block name="joint_origin"/> -->
      <geometry>
        <!-- <cylinder radius="${wheel_radius}" length="${wheel_length}"/> -->
        <mesh filename="package://raspimouse_description/meshes/dae/wheel/RasPiMouse_wheel.dae"/>
      </geometry>
    </collision>
    <inertial>
      <origin xyz="-0.000107 0 0.002875"/>
      <mass value="0.0113"/>
      <inertia ixx="0.000002208187" ixy="0.000000000001" ixz="0.000000004787" iyy="0.00000218412" iyz="0.000000000003" izz="0.000004078299"/>
    </inertial>
  </link>
  <joint name="rf_joint" type="fixed">
    <origin rpy="0 0 0" xyz="0.04 -0.045 0.032"/>
    <parent link="base_link"/>
    <child link="rf"/>
  </joint>
  <link name="rf">
    <visual>
      <geometry>
        <box size="0.01 0.005 0.007"/>
      </geometry>
    </visual>
    <material name="grey">
      <color rgba="0.5 0.5 0.5 1"/>
    </material>
    <inertial>
      <mass value="0.000001"/>
      <origin xyz="0 0 0"/>
      <inertia ixx="0.0001" ixy="0.0" ixz="0.0" iyy="0.0001" iyz="0.0" izz="0.0001"/>
    </inertial>
  </link>
  <!-- Set up laser gazebo details -->
  <hokuyo_laser/>
  <joint name="rs_joint" type="fixed">
    <origin rpy="0 0 -1.04" xyz="0.059 -0.01 0.032"/>
    <parent link="base_link"/>
    <child link="rs"/>
  </joint>
  <link name="rs">
    <visual>
      <geometry>
        <box size="0.01 0.005 0.007"/>
      </geometry>
    </visual>
    <material name="grey">
      <color rgba="0.5 0.5 0.5 1"/>
    </material>
    <inertial>
      <mass value="0.000001"/>
      <origin xyz="0 0 0"/>
      <inertia ixx="0.0001" ixy="0.0" ixz="0.0" iyy="0.0001" iyz="0.0" izz="0.0001"/>
    </inertial>
  </link>
  <!-- Set up laser gazebo details -->
  <hokuyo_laser/>
  <joint name="ls_joint" type="fixed">
    <origin rpy="0 0 1.04" xyz="0.059 0.01 0.032"/>
    <parent link="base_link"/>
    <child link="ls"/>
  </joint>
  <link name="ls">
    <visual>
      <geometry>
        <box size="0.01 0.005 0.007"/>
      </geometry>
    </visual>
    <material name="grey">
      <color rgba="0.5 0.5 0.5 1"/>
    </material>
    <inertial>
      <mass value="0.000001"/>
      <origin xyz="0 0 0"/>
      <inertia ixx="0.0001" ixy="0.0" ixz="0.0" iyy="0.0001" iyz="0.0" izz="0.0001"/>
    </inertial>
  </link>
  <!-- Set up laser gazebo details -->
  <hokuyo_laser/>
  <joint name="lf_joint" type="fixed">
    <origin rpy="0 0 0" xyz="0.04 0.045 0.032"/>
    <parent link="base_link"/>
    <child link="lf"/>
  </joint>
  <link name="lf">
    <visual>
      <geometry>
        <box size="0.01 0.005 0.007"/>
      </geometry>
    </visual>
    <material name="grey">
      <color rgba="0.5 0.5 0.5 1"/>
    </material>
    <inertial>
      <mass value="0.000001"/>
      <origin xyz="0 0 0"/>
      <inertia ixx="0.0001" ixy="0.0" ixz="0.0" iyy="0.0001" iyz="0.0" izz="0.0001"/>
    </inertial>
  </link>
  <!-- Set up laser gazebo details -->
  <hokuyo_laser/>
  <transmission name="right_wheel_trans">
    <type>transmission_interface/SimpleTransmission</type>
    <joint name="right_wheel_joint">
      <hardwareInterface>hardware_interface/VelocityJointInterface</hardwareInterface>
    </joint>
    <actuator name="right_wheel_motor">
      <hardwareInterface>hardware_interface/VelocityJointInterface</hardwareInterface>
    </actuator>
  </transmission>
  <transmission name="left_wheel_trans">
    <type>transmission_interface/SimpleTransmission</type>
    <joint name="left_wheel_joint">
      <hardwareInterface>hardware_interface/VelocityJointInterface</hardwareInterface>
    </joint>
    <actuator name="left_wheel_motor">
      <hardwareInterface>hardware_interface/VelocityJointInterface</hardwareInterface>
    </actuator>
  </transmission>
  <!-- EffortJointInterface: requires position, velocity, effort -->
  <!-- <xacro:wheel_trans prefix="right" interface="EffortJointInterface"/> -->
  <!-- <xacro:wheel_trans prefix="left" interface="EffortJointInterface"/> -->
  <gazebo reference="base_link">
    <!-- <selfCollide>true</selfCollide> -->
    <!-- <mu1 value="0.05" /> -->
    <!-- <mu2 value="0.05" /> -->
    <mu1>0.05</mu1>
    <mu2>0.05</mu2>
  </gazebo>
  <gazebo reference="right_wheel">
    <!-- <selfCollide>true</selfCollide> -->
    <!--   <mu1 value="0.8" /> -->
    <!--   <mu2 value="0.8" /> -->
    <mu1>10.0</mu1>
    <mu2>10.0</mu2>
    <kp>1000000.0</kp>
    <kd>100.0</kd>
    <minDepth>0.001</minDepth>
    <maxVel>1.0</maxVel>
  </gazebo>
  <gazebo reference="left_wheel">
    <!-- <selfCollide>true</selfCollide> -->
    <!--   <mu1 value="0.8" /> -->
    <!--   <mu2 value="0.8" /> -->
    <mu1>10.0</mu1>
    <mu2>10.0</mu2>
    <kp>1000000.0</kp>
    <kd>100.0</kd>
    <minDepth>0.001</minDepth>
    <maxVel>1.0</maxVel>
  </gazebo>
  <gazebo reference="rf">
    <sensor name="rf_lightsensor" type="ray">
      <pose>0 0 0 0 0 0</pose>
      <visualize>false</visualize>
      <update_rate>20</update_rate>
      <ray>
        <scan>
          <horizontal>
            <!-- <samples>720</samples> -->
            <samples>1</samples>
            <resolution>1</resolution>
            <min_angle>-0.15</min_angle>
            <max_angle>0.15</max_angle>
          </horizontal>
        </scan>
        <range>
          <min>0.01</min>
          <max>0.6</max>
          <resolution>0.001</resolution>
        </range>
        <noise>
          <type>gaussian</type>
          <mean>0.0</mean>
          <stddev>0.01</stddev>
        </noise>
      </ray>
      <plugin filename="libgazebo_ros_laser.so" name="gazebo_ros_rf_lightsensor_controller">
        <topicName>/raspimouse_on_gazebo/rf_scan</topicName>
        <frameName>rf</frameName>
      </plugin>
    </sensor>
  </gazebo>
  <gazebo reference="rs">
    <sensor name="rs_lightsensor" type="ray">
      <pose>0 0 0 0 0 0</pose>
      <visualize>false</visualize>
      <update_rate>20</update_rate>
      <ray>
        <scan>
          <horizontal>
            <!-- <samples>720</samples> -->
            <samples>1</samples>
            <resolution>1</resolution>
            <min_angle>-1.19</min_angle>
            <max_angle>-0.89</max_angle>
          </horizontal>
        </scan>
        <range>
          <min>0.01</min>
          <max>0.6</max>
          <resolution>0.001</resolution>
        </range>
        <noise>
          <type>gaussian</type>
          <mean>0.0</mean>
          <stddev>0.01</stddev>
        </noise>
      </ray>
      <plugin filename="libgazebo_ros_laser.so" name="gazebo_ros_rs_lightsensor_controller">
        <topicName>/raspimouse_on_gazebo/rs_scan</topicName>
        <frameName>rs</frameName>
      </plugin>
    </sensor>
  </gazebo>
  <gazebo reference="ls">
    <sensor name="ls_lightsensor" type="ray">
      <pose>0 0 0 0 0 0</pose>
      <visualize>false</visualize>
      <update_rate>20</update_rate>
      <ray>
        <scan>
          <horizontal>
            <!-- <samples>720</samples> -->
            <samples>1</samples>
            <resolution>1</resolution>
            <min_angle>0.89</min_angle>
            <max_angle>1.19</max_angle>
          </horizontal>
        </scan>
        <range>
          <min>0.01</min>
          <max>0.6</max>
          <resolution>0.001</resolution>
        </range>
        <noise>
          <type>gaussian</type>
          <mean>0.0</mean>
          <stddev>0.01</stddev>
        </noise>
      </ray>
      <plugin filename="libgazebo_ros_laser.so" name="gazebo_ros_ls_lightsensor_controller">
        <topicName>/raspimouse_on_gazebo/ls_scan</topicName>
        <frameName>ls</frameName>
      </plugin>
    </sensor>
  </gazebo>
  <gazebo reference="lf">
    <sensor name="lf_lightsensor" type="ray">
      <pose>0 0 0 0 0 0</pose>
      <visualize>false</visualize>
      <update_rate>20</update_rate>
      <ray>
        <scan>
          <horizontal>
            <!-- <samples>720</samples> -->
            <samples>1</samples>
            <resolution>1</resolution>
            <min_angle>-0.15</min_angle>
            <max_angle>0.15</max_angle>
          </horizontal>
        </scan>
        <range>
          <min>0.01</min>
          <max>0.6</max>
          <resolution>0.001</resolution>
        </range>
        <noise>
          <type>gaussian</type>
          <mean>0.0</mean>
          <stddev>0.01</stddev>
        </noise>
      </ray>
      <plugin filename="libgazebo_ros_laser.so" name="gazebo_ros_lf_lightsensor_controller">
        <topicName>/raspimouse_on_gazebo/lf_scan</topicName>
        <frameName>lf</frameName>
      </plugin>
    </sensor>
  </gazebo>
  <raspimouse_on_gazebo/>
  <!-- =============== Gazebo =============== -->
  <gazebo>
    <plugin filename="libgazebo_ros_control.so" name="gazebo_ros_control">
      <robotNamespace>raspimouse_on_gazebo</robotNamespace>
    </plugin>
  </gazebo>
</robot>

